<robot name="simple_box">
  <link name="my_box">
    <inertial>
      <origin xyz="0 0 0.5" /> 
      <mass value="1.0" />
      <inertia  ixx="1.0" ixy="0.0"  ixz="0.0"  iyy="100.0"  iyz="0.0"  izz="1.0" />
    </inertial>
    <visual>
      <origin xyz="0 0 0.5"/>
      <geometry>
        <box size="1 1 1" />
      </geometry>
    </visual>
    <collision>
      <origin xyz="0 0 0.5"/>
      <geometry>
        <box size="1 1 1" />
      </geometry>
    </collision>
  </link>

 <link
    name="left wheel">
    <inertial>
      <origin
        xyz="0 0 0"
        rpy="0 0 0" />
      <mass
        value="0.47553449779267" />
      <inertia
        ixx="0.00490966460932713"
        ixy="-3.54087862241003E-19"
        ixz="-1.51683481439318E-19"
        iyy="0.00292364483627101"
        iyz="2.366776865394E-34"
        izz="0.00292364483627101" />
    </inertial>
    <visual>
      <origin
        xyz="0 0 0"
        rpy="0 0 0" />
      <geometry>
        <mesh
          filename="package://rbe_500_model/meshes/left wheel.STL" />
      </geometry>
      <material
        name="">
        <color
          rgba="0.294117647058824 0.294117647058824 0.294117647058824 1" />
      </material>
    </visual>
    <collision>
      <origin
        xyz="0 0 0"
        rpy="0 0 0" />
      <geometry>
        <mesh
          filename="package://rbe_500_model/meshes/left wheel.STL" />
      </geometry>
    </collision>
  </link>
  <joint
    name="LWG"
    type="continuous">
    <origin
      xyz="-0.575 -0.5 0"
      rpy="0 0 0 " />
    <parent
      link="my_box" />
    <child
      link="left wheel" />
    <axis
      xyz="1 0 0" />
  </joint>

  <link
    name="Right Wheel">
    <inertial>
      <origin
        xyz="0 0 0"
        rpy="0 0 0" />
      <mass
        value="0.47553449779267" />
      <inertia
        ixx="0.00490966460932714"
        ixy="-2.23246185292269E-18"
        ixz="-9.22234923881454E-20"
        iyy="0.00292364483627102"
        iyz="-1.33222993581309E-19"
        izz="0.00292364483627102" />
    </inertial>
    <visual>
      <origin
        xyz="0 0 0"
        rpy="0 0 0" />
      <geometry>
        <mesh
          filename="package://rbe_500_model/meshes/left wheel.STL" />
      </geometry>
      <material
        name="">
        <color
          rgba="0.294117647058824 0.294117647058824 0.294117647058824 1" />
      </material>
    </visual>
    <collision>
      <origin
        xyz="0 0 0"
        rpy="0 0 0" />
      <geometry>
        <mesh
          filename="package://rbe_500_model/meshes/left wheel.STL" />
      </geometry>
    </collision>
  </link>
  <joint
    name="Right Wheel"
    type="continuous">
    <origin
      xyz="0.5 -0.5 0"
      rpy="0 0 0" />
    <parent
      link="my_box" />
    <child
      link="Right Wheel" />
    <axis
      xyz="1 0 0" />
  </joint>

  <link name="caster">
  	<interial> 
	<origin xyz="0 0 0.0" /> 
      <mass value="1.0" />
      <inertia  ixx="1.0" ixy="0.0"  ixz="0.0"  iyy="100.0"  iyz="0.0"  izz="1.0" />
    </inertial>
    <visual>
      <origin xyz="0 0 0.0"/>
      <geometry>
        <box size="1 1 1" />
      </geometry>
    </visual>
    <collision>
      <origin xyz="0 0 0.5"/>
      <geometry>
        <box size="0.127 0.127 0.127" />
      </geometry>
    </collision>
  </link>
  <joint name="caster" type="floating">
	<origin
      xyz="-0.5 0 0"
      rpy="0 0 0" />
    <parent
      link="my_box" />
    <child
      link="caster" />
    <axis
      xyz="1 1 1" />


  <gazebo reference="my_box">
    <material>Gazebo/Blue</material>
  </gazebo>
</robot>
